Workbook

Sheet Assumptions
B1: YETI Holdings — Model Assumptions | C1: 2021 | D1: 2022 | E1: 2023 | F1: 2024 | G1: 2025 | H1: 2026 | I1: 2027 | J1: 2028 | K1: 2029 | L1: 2030
B2: Assumption | C2: Historical | D2: Historical | E2: Historical | F2: Historical | G2: Historical | H2: Projected | I2: Projected | J2: Projected | K2: Projected | L2: Projected
B3: INCOME STATEMENT
B4: Revenue Growth YoY | C4: N/A | D4: =IFERROR(('Income-Statement'!D4-'Income-Statement'!C4)/'Income-Statement'!C4, 0) -> 0.13057012 | E4: =IFERROR(('Income-Statement'!E4-'Income-Statement'!D4)/'Income-Statement'!D4,0) -> 0.03980073 | F4: =IFERROR(('Income-Statement'!F4-'Income-Statement'!E4)/'Income-Statement'!E4,0) -> 0.10318844 | G4: =IFERROR(('Income-Statement'!G4-'Income-Statement'!F4)/'Income-Statement'!F4,0) -> 0.021105836 | H4: 0.04 | I4: 0.04 | J4: 0.045 | K4: 0.045 | L4: 0.05 | M4: Reasonable middle ground as Yeti's growth was slowing from 13.1% in 2022 to 2.1% in 2025
B5: Gross Margin % | C5: =IFERROR('Income-Statement'!C6/'Income-Statement'!C4,0) -> 0.57839785 | D5: =IFERROR('Income-Statement'!D6/'Income-Statement'!D4,0) -> 0.47855471 | E5: =IFERROR('Income-Statement'!E6/'Income-Statement'!E4,0) -> 0.56862519 | F5: =IFERROR('Income-Statement'!F6/'Income-Statement'!F4,0) -> 0.58106983 | G5: =IFERROR('Income-Statement'!G6/'Income-Statement'!G4,0) -> 0.57409015 | H5: 0.574 | I5: 0.576 | J5: 0.578 | K5: 0.58 | L5: 0.582 | M5: held near the 2025 actual of 57.4% and nudged slightly higher assuming supply chain improvements over time.
B6: SG&A % of Revenue | C6: =IFERROR('Income-Statement'!C7/'Income-Statement'!C4,0) -> 0.38354303 | D6: =IFERROR('Income-Statement'!D7/'Income-Statement'!D4,0) -> 0.39934254 | E6: =IFERROR('Income-Statement'!E7/'Income-Statement'!E4,0) -> 0.43270174 | F6: =IFERROR('Income-Statement'!F7/'Income-Statement'!F4,0) -> 0.44697528 | G6: =IFERROR('Income-Statement'!G7/'Income-Statement'!G4,0) -> 0.4597965 | H6: 0.457 | I6: 0.454 | J6: 0.451 | K6: 0.449 | L6: 0.447 | M6: gradually declining because as revenue scales, fixed overhead costs become a smaller slice of the overall company
B7: Effective Tax Rate | C7: =IFERROR(ABS('Income-Statement'!C12/'Income-Statement'!C11),0) -> 0.20792072 | D7: =IFERROR(ABS('Income-Statement'!D12/'Income-Statement'!D11),0) -> 0.22796251 | E7: =IFERROR(ABS('Income-Statement'!E12/'Income-Statement'!E11),0) -> 0.24811681 | F7: =IFERROR(ABS('Income-Statement'!F12/'Income-Statement'!F11),0) -> 0.24547774 | G7: =IFERROR(ABS('Income-Statement'!G12/'Income-Statement'!G11),0) -> 0.24919989 | H7: 0.25 | I7: 0.25 | J7: 0.25 | K7: 0.25 | L7: 0.25 | M7: rounded up slightly from YETI's historical average to be conservative, since corporate tax rates have more political risk of going up rather than down
B8: Interest Income / Expense ($000s) | C8: ='Income-Statement'!C9 -> -3339 | D8: ='Income-Statement'!D9 -> -4466 | E8: ='Income-Statement'!E9 -> -942 | F8: ='Income-Statement'!F9 -> 660 | G8: ='Income-Statement'!G9 -> -443 | H8: ='Income-Statement'!G9 -> -443 | I8: ='Income-Statement'!G9 -> -443 | J8: ='Income-Statement'!G9 -> -443 | K8: ='Income-Statement'!G9 -> -443 | L8: ='Income-Statement'!G9 -> -443 | M8: held at 443k because I'm not modeling new borrowing
B9: BALANCE SHEET — WORKING CAPITAL
B10: Days Sales Outstanding (DSO) | C10: =IFERROR(('Balance-Sheet'!C6/'Income-Statement'!C4)*365,0) -> 28.333637 | D10: =IFERROR(('Balance-Sheet'!D6/'Income-Statement'!D4)*365,0) -> 18.177903 | E10: =IFERROR(('Balance-Sheet'!E6/'Income-Statement'!E4)*365,0) -> 21.07508 | F10: =IFERROR(('Balance-Sheet'!F6/'Income-Statement'!F4)*365,0) -> 23.973986 | G10: =IFERROR(('Balance-Sheet'!G6/'Income-Statement'!G4)*365,0) -> 27.626399 | H10: 28 | I10: 28 | J10: 28 | K10: 28 | L10: 28 | M10: held near 2025 actual of 27.6 assuming Yeti collections stays consistent
B11: Days Inventory Outstanding (DIO) | C11: =IFERROR(('Balance-Sheet'!C7/'Income-Statement'!C5)*365,0) -> 195.64642 | D11: =IFERROR(('Balance-Sheet'!D7/'Income-Statement'!D5)*365,0) -> 162.97422 | E11: =IFERROR(('Balance-Sheet'!E7/'Income-Statement'!E5)*365,0) -> 172.01436 | F11: =IFERROR(('Balance-Sheet'!F7/'Income-Statement'!F5)*365,0) -> 147.62953 | G11: =IFERROR(('Balance-Sheet'!G7/'Income-Statement'!G5)*365,0) -> 133.28937 | H11: 135 | I11: 133 | J11: 131 | K11: 130 | L11: 130 | M11: held near 2025 of 133 days assuming modest inventory improvements
B12: Days Payable Outstanding (DPO) | C12: =IFERROR(('Balance-Sheet'!C17/'Income-Statement'!C5)*365,0) -> 117.38822 | D12: =IFERROR(('Balance-Sheet'!D17/'Income-Statement'!D5)*365,0) -> 61.790421 | E12: =IFERROR(('Balance-Sheet'!E17/'Income-Statement'!E5)*365,0) -> 97.121534 | F12: =IFERROR(('Balance-Sheet'!F17/'Income-Statement'!F5)*365,0) -> 75.466952 | G12: =IFERROR(('Balance-Sheet'!G17/'Income-Statement'!G5)*365,0) -> 60.206814 | H12: 62 | I12: 62 | J12: 62 | K12: 62 | L12: 62 | M12: assuming supplier payments remain stable
B13: Operating Margin % (derived) | C13: =IFERROR('Income-Statement'!C8/'Income-Statement'!C4,0) -> 0.19485481 | D13: =IFERROR('Income-Statement'!D8/'Income-Statement'!D4,0) -> 0.079212172 | E13: =IFERROR('Income-Statement'!E8/'Income-Statement'!E4,0) -> 0.13592345 | F13: =IFERROR('Income-Statement'!F8/'Income-Statement'!F4,0) -> 0.13409455 | G13: =IFERROR('Income-Statement'!G8/'Income-Statement'!G4,0) -> 0.11429365 | H13: =IFERROR('Income-Statement'!H8/'Income-Statement'!H4,0) -> 0.117 | I13: =IFERROR('Income-Statement'!I8/'Income-Statement'!I4,0) -> 0.122 | J13: =IFERROR('Income-Statement'!J8/'Income-Statement'!J4,0) -> 0.127 | ... L13: =IFERROR('Income-Statement'!L8/'Income-Statement'!L4,0) -> 0.135
B14: CAPEX & D&A
B15: Capex % of Revenue | C15: =IFERROR(ABS('Cash-Flow'!C23)/'Income-Statement'!C4,0) -> 0.039774229 | D15: =IFERROR(ABS('Cash-Flow'!D23)/'Income-Statement'!D4,0) -> 0.028791604 | E15: =IFERROR(ABS('Cash-Flow'!E23)/'Income-Statement'!E4,0) -> 0.030548986 | F15: =IFERROR(ABS('Cash-Flow'!F23)/'Income-Statement'!F4,0) -> 0.022860603 | G15: =IFERROR(ABS('Cash-Flow'!G23)/'Income-Statement'!G4,0) -> 0.022834968 | H15: 0.024 | I15: 0.024 | J15: 0.023 | K15: 0.023 | L15: 0.023 | M15: held near 2.3-2.4% since Yeti isn't in a heavy investment cycle
B16: D&A % of Revenue | C16: =IFERROR('Cash-Flow'!C6/'Income-Statement'!C4,0) -> 0.022728738 | D16: =IFERROR('Cash-Flow'!D6/'Income-Statement'!D4,0) -> 0.024978968 | E16: =IFERROR('Cash-Flow'!E6/'Income-Statement'!E4,0) -> 0.027993993 | F16: =IFERROR('Cash-Flow'!F6/'Income-Statement'!F4,0) -> 0.026303465 | G16: =IFERROR('Cash-Flow'!G6/'Income-Statement'!G4,0) -> 0.029024444 | H16: 0.03 | I16: 0.03 | J16: 0.03 | K16: 0.03 | L16: 0.029 | M16: consistent with recent trend
B17: Stock-Based Comp % of Revenue | C17: =IFERROR('Cash-Flow'!C8/'Income-Statement'!C4,0) -> 0.010966776 | D17: =IFERROR('Cash-Flow'!D8/'Income-Statement'!D4,0) -> 0.011157695 | E17: =IFERROR('Cash-Flow'!E8/'Income-Statement'!E4,0) -> 0.017965736 | F17: =IFERROR('Cash-Flow'!F8/'Income-Statement'!F4,0) -> 0.022252364 | G17: =IFERROR('Cash-Flow'!G8/'Income-Statement'!G4,0) -> 0.025522158 | H17: ='Cash-Flow'!G8/'Income-Statement'!G4 -> 0.025522158 | I17: ='Cash-Flow'!G8/'Income-Statement'!G4 -> 0.025522158 | J17: ='Cash-Flow'!G8/'Income-Statement'!G4 -> 0.025522158 | K17: ='Cash-Flow'!G8/'Income-Statement'!G4 -> 0.025522158 | L17: ='Cash-Flow'!G8/'Income-Statement'!G4 -> 0.025522158 | M17: roughly matches US GDP growth rate
B18: Note: Blue = hardcoded input | Yellow highlight = key driver
B19: Green = cross-sheet formula | All $ in thousands
B20: FORMULA REFERENCE — Where Each Assumption Comes From
B21: Assumption | C21: Formula Logic | D21: Source Cells
B22: Revenue Growth YoY | C22: (Revenue_t - Revenue_t-1) / Revenue_t-1 | D22: Income-Statement row 4 (Net Sales)
B23: Gross Margin % | C23: Gross Profit / Net Sales | D23: Income-Statement rows 6 ÷ 4
B24: SG&A % of Revenue | C24: SG&A / Net Sales | D24: Income-Statement rows 7 ÷ 4
B25: Effective Tax Rate | C25: ABS(Tax Expense / Income Before Taxes) | D25: Income-Statement rows 12 ÷ 11
B26: Interest Expense | C26: Direct link to IS Interest line | D26: Income-Statement row 9
B27: DSO | C27: (Accounts Receivable / Revenue) x 365 | D27: Balance-Sheet row 6 ÷ Income-Statement row 4
B28: DIO | C28: (Inventory / COGS) x 365 | D28: Balance-Sheet row 7 ÷ Income-Statement row 5
B29: DPO | C29: (Accounts Payable / COGS) x 365 | D29: Balance-Sheet row 17 ÷ Income-Statement row 5
B30: Capex % of Revenue | C30: ABS(Capex) / Revenue | D30: Cash-Flow row 23 ÷ Income-Statement row 4
B31: D&A % of Revenue | C31: D&A / Revenue | D31: Cash-Flow row 6 ÷ Income-Statement row 4
B32: SBC % of Revenue | C32: Stock-Based Comp / Revenue | D32: Cash-Flow row 8 ÷ Income-Statement row 4
B33: Operating Margin % (ref) | C33: Operating Income / Revenue [derived, not an input] | D33: Income-Statement rows 8 ÷ 4

Sheet Income-Statement
B1: YETI Holdings, Inc. — Consolidated Income Statement (In Thousands)
B2: ($000s)
C3: 2021 | D3: 2022 | E3: 2023 | F3: 2024 | G3: 2025 | H3: 2026 | I3: 2027 | J3: 2028 | K3: 2029 | L3: 2030
B4: Net Sales | C4: 1410989 | D4: 1595222 | E4: 1658713 | F4: 1829873 | G4: 1868494 | H4: =G4*(1+Assumptions!H4) -> 1943233.8 | I4: =H4*(1+Assumptions!I4) -> 2020963.1 | J4: =I4*(1+Assumptions!J4) -> 2111906.5 | K4: =J4*(1+Assumptions!K4) -> 2206942.2 | L4: =K4*(1+Assumptions!L4) -> 2317289.4
B5: COGS | C5: 594876 | D5: 831821 | E5: 715527 | F5: 766589 | G5: 795810 | H5: =H4*(1-Assumptions!H5) -> 827817.58 | I5: =I4*(1-Assumptions!I5) -> 856888.36 | J5: =J4*(1-Assumptions!J5) -> 891224.52 | K5: =K4*(1-Assumptions!K5) -> 926915.74 | L5: =L4*(1-Assumptions!L5) -> 968626.95
B6: Gross Profit | C6: 816113 | D6: 763401 | E6: 943186 | F6: 1063284 | G6: 1072684 | H6: =H4-H5 -> 1115416.2 | I6: =I4-I5 -> 1164074.8 | J6: =J4-J5 -> 1220681.9 | K6: =K4-K5 -> 1280026.5 | L6: =L4-L5 -> 1348662.4
B7: SG&A Expenses | C7: 541175 | D7: 637040 | E7: 717728 | F7: 817908 | G7: 859127 | H7: =H4*Assumptions!H6 -> 888057.83 | I7: =I4*Assumptions!I6 -> 917517.25 | J7: =J4*Assumptions!J6 -> 952469.81 | K7: =K4*Assumptions!K6 -> 990917.07 | L7: =L4*Assumptions!L6 -> 1035828.3
B8: Operating Income | C8: 274938 | D8: 126361 | E8: 225458 | F8: 245376 | G8: 213557 | H8: =H6-H7 -> 227358.35 | I8: =I6-I7 -> 246557.5 | J8: =J6-J7 -> 268212.12 | K8: =K6-K7 -> 289109.43 | L8: =L6-L7 -> 312834.06
B9: Interest Income/Expense | C9: -3339 | D9: -4466 | E9: -942 | F9: 660 | G9: -443 | H9: =G9 -> -443 | I9: =G9 -> -443 | J9: =G9 -> -443 | K9: =G9 -> -443 | L9: =G9 -> -443
B10: Other Income/Expense | C10: -3189 | D10: -5718 | E10: 1430 | F10: -13188 | G10: 7167 | H10: 0 | I10: 0 | J10: 0 | K10: 0 | L10: 0
B11: Income Before Taxes | C11: 268410 | D11: 116177 | E11: 225946 | F11: 232848 | G11: 220281 | H11: =H8+H9+H10 -> 226915.35 | I11: =I8+I9+I10 -> 246114.5 | J11: =J8+J9+J10 -> 267769.12 | K11: =K8+K9+K10 -> 288666.43 | L11: =L8+L9+L10 -> 312391.06
B12: Income Tax Expense | C12: -55808 | D12: -26484 | E12: -56061 | F12: -57159 | G12: -54894 | H12: =-H11*Assumptions!H7 -> -56728.837 | I12: =-I11*Assumptions!I7 -> -61528.625 | J12: =-J11*Assumptions!J7 -> -66942.28 | K12: =-K11*Assumptions!K7 -> -72166.608 | L12: =-L11*Assumptions!L7 -> -78097.766
B13: Net Income | C13: 212602 | D13: 89693 | E13: 169885 | F13: 175689 | G13: 165387 | H13: =H11+H12 -> 170186.51 | I13: =I11+I12 -> 184585.87 | J13: =J11+J12 -> 200826.84 | K13: =K11+K12 -> 216499.83 | L13: =L11+L12 -> 234293.3
B15: Key Margins
B16: Gross Margin % | C16: =C6/C4 -> 0.57839785 | D16: =D6/D4 -> 0.47855471 | E16: =E6/E4 -> 0.56862519 | F16: =F6/F4 -> 0.58106983 | G16: =G6/G4 -> 0.57409015 | H16: =H6/H4 -> 0.574 | I16: =I6/I4 -> 0.576 | J16: =J6/J4 -> 0.578 | ... L16: =L6/L4 -> 0.582
B17: Operating Margin % | C17: =C8/C4 -> 0.19485481 | D17: =D8/D4 -> 0.079212172 | E17: =E8/E4 -> 0.13592345 | F17: =F8/F4 -> 0.13409455 | G17: =G8/G4 -> 0.11429365 | H17: =H8/H4 -> 0.117 | I17: =I8/I4 -> 0.122 | J17: =J8/J4 -> 0.127 | ... L17: =L8/L4 -> 0.135
B18: Net Margin % | C18: =C13/C4 -> 0.15067587 | D18: =D13/D4 -> 0.05622603 | E18: =E13/E4 -> 0.10241977 | F18: =F13/F4 -> 0.096011581 | G18: =G13/G4 -> 0.08851353 | H18: =H13/H4 -> 0.087579022 | I18: =I13/I4 -> 0.091335598 | J18: =J13/J4 -> 0.095092678 | ... L18: =L13/L4 -> 0.10110662

Sheet Balance-Sheet
B1: YETI Holdings, Inc. — Consolidated Balance Sheet (In Thousands)
C3: 2021 | D3: 2022 | E3: 2023 | F3: 2024 | G3: 2025 | H3: 2026 | I3: 2027 | J3: 2028 | K3: 2029 | L3: 2030
B4: ASSETS
B5: Cash | C5: 312189 | D5: 234741 | E5: 438960 | F5: 358795 | G5: 188342 | H5: =(H27+H34)-SUM(H6:H8)-SUM(H10:H14) -> 386311.4 | I5: =(I27+I34)-SUM(I6:I8)-SUM(I10:I14) -> 577979.27 | J5: =(J27+J34)-SUM(J6:J8)-SUM(J10:J14) -> 787934.22 | K5: =(K27+K34)-SUM(K6:K8)-SUM(K10:K14) -> 1011892.4 | L5: =(L27+L34)-SUM(L6:L8)-SUM(L10:L14) -> 1248614.9
B6: Accounts Receivable, net | C6: 109530 | D6: 79446 | E6: 95774 | F6: 120190 | G6: 141424 | H6: ='Income-Statement'!H4/365*Assumptions!H10 -> 149069.99 | I6: ='Income-Statement'!I4/365*Assumptions!I10 -> 155032.79 | J6: ='Income-Statement'!J4/365*Assumptions!J10 -> 162009.26 | K6: ='Income-Statement'!K4/365*Assumptions!K10 -> 169299.68 | L6: ='Income-Statement'!L4/365*Assumptions!L10 -> 177764.66
B7: Inventory | C7: 318864 | D7: 371412 | E7: 337208 | F7: 310058 | G7: 290611 | H7: ='Income-Statement'!H5/365*Assumptions!H11 -> 306179.11 | I7: ='Income-Statement'!I5/365*Assumptions!I11 -> 312236.03 | J7: ='Income-Statement'!J5/365*Assumptions!J11 -> 319864.14 | K7: ='Income-Statement'!K5/365*Assumptions!K11 -> 330134.37 | L7: ='Income-Statement'!L5/365*Assumptions!L11 -> 344990.42
B8: Prepaid expenses & other current assets | C8: 29584 | D8: 33321 | E8: 42463 | F8: 37723 | G8: 39949 | H8: ='Income-Statement'!H4*IFERROR(AVERAGE('Balance-Sheet'!C8/'Income-Statement'!C4,'Balance-Sheet'!D8/'Income-Statement'!D4,'Balance-Sheet'!E8/'Income-Statement'!E4,'Balance-Sheet'!F8/'Income-Statement'!F4,'Balance-Sheet'!G8/'Income-Statement'!G4),0.021) -> 42537.479 | I8: ='Income-Statement'!I4*IFERROR(AVERAGE('Balance-Sheet'!C8/'Income-Statement'!C4,'Balance-Sheet'!D8/'Income-Statement'!D4,'Balance-Sheet'!E8/'Income-Statement'!E4,'Balance-Sheet'!F8/'Income-Statement'!F4,'Balance-Sheet'!G8/'Income-Statement'!G4),0.021) -> 44238.978 | J8: ='Income-Statement'!J4*IFERROR(AVERAGE('Balance-Sheet'!C8/'Income-Statement'!C4,'Balance-Sheet'!D8/'Income-Statement'!D4,'Balance-Sheet'!E8/'Income-Statement'!E4,'Balance-Sheet'!F8/'Income-Statement'!F4,'Balance-Sheet'!G8/'Income-Statement'!G4),0.021) -> 46229.732 | K8: ='Income-Statement'!K4*IFERROR(AVERAGE('Balance-Sheet'!C8/'Income-Statement'!C4,'Balance-Sheet'!D8/'Income-Statement'!D4,'Balance-Sheet'!E8/'Income-Statement'!E4,'Balance-Sheet'!F8/'Income-Statement'!F4,'Balance-Sheet'!G8/'Income-Statement'!G4),0.021) -> 48310.07 | L8: ='Income-Statement'!L4*IFERROR(AVERAGE('Balance-Sheet'!C8/'Income-Statement'!C4,'Balance-Sheet'!D8/'Income-Statement'!D4,'Balance-Sheet'!E8/'Income-Statement'!E4,'Balance-Sheet'!F8/'Income-Statement'!F4,'Balance-Sheet'!G8/'Income-Statement'!G4),0.021) -> 50725.573
B9: Total Current Assets | C9: =SUM(C5:C8) -> 770167 | D9: =SUM(D5:D8) -> 718920 | E9: =SUM(E5:E8) -> 914405 | F9: =SUM(F5:F8) -> 826766 | G9: =SUM(G5:G8) -> 660326 | H9: =SUM(H5:H8) -> 884097.97 | I9: =SUM(I5:I8) -> 1089487.1 | J9: =SUM(J5:J8) -> 1316037.4 | ... L9: =SUM(L5:L8) -> 1822095.5
B10: Property & Equipment, net | C10: 119044 | D10: 124587 | E10: 130714 | F10: 126270 | G10: 142105 | H10: =G10+'Income-Statement'!H4*Assumptions!H15-'Income-Statement'!H4*Assumptions!H16 -> 130445.6 | I10: =H10+'Income-Statement'!I4*Assumptions!I15-'Income-Statement'!I4*Assumptions!I16 -> 118319.82 | J10: =I10+'Income-Statement'!J4*Assumptions!J15-'Income-Statement'!J4*Assumptions!J16 -> 103536.47 | K10: =J10+'Income-Statement'!K4*Assumptions!K15-'Income-Statement'!K4*Assumptions!K16 -> 88087.878 | L10: =K10+'Income-Statement'!L4*Assumptions!L15-'Income-Statement'!L4*Assumptions!L16 -> 74184.142
B11: Operating lease ROU Assets | C11: 54971 | D11: 55406 | E11: 77556 | F11: 78279 | G11: 131531 | H11: =G11 -> 131531 | I11: =H11 -> 131531 | J11: =I11 -> 131531 | K11: =J11 -> 131531 | L11: =K11 -> 131531
B12: Goodwill | C12: 54293 | D12: 54293 | E12: 54293 | F12: 72557 | G12: 72308 | H12: =G12 -> 72308 | I12: =H12 -> 72308 | J12: =I12 -> 72308 | K12: =J12 -> 72308 | L12: =K12 -> 72308
B13: Intangible assets, net | C13: 95314 | D13: 99429 | E13: 117629 | F13: 172023 | G13: 219791 | H13: =G13 -> 219791 | I13: =H13 -> 219791 | J13: =I13 -> 219791 | K13: =J13 -> 219791 | L13: =K13 -> 219791
B14: Other assets | C14: 2575 | D14: 24130 | E14: 2595 | F14: 10225 | G14: 9357 | H14: =G14 -> 9357 | I14: =H14 -> 9357 | J14: =I14 -> 9357 | K14: =J14 -> 9357 | L14: =K14 -> 9357
B15: Total Assets | C15: =SUM(C9:C14) -> 1096364 | D15: =SUM(D9:D14) -> 1076765 | E15: =SUM(E9:E14) -> 1297192 | F15: =SUM(F9:F14) -> 1286120 | G15: =SUM(G9:G14) -> 1235418 | H15: =SUM(H9:H14) -> 1447530.6 | I15: =SUM(I9:I14) -> 1640793.9 | J15: =SUM(J9:J14) -> 1852560.8 | ... L15: =SUM(L9:L14) -> 2329266.7
B16: LIABILITIES AND STOCKHOLDERS EQUITY
B17: Accounts Payable | C17: 191319 | D17: 140818 | E17: 190392 | F17: 158499 | G17: 131269 | H17: ='Income-Statement'!H5/365*Assumptions!H12 -> 140615.59 | I17: ='Income-Statement'!I5/365*Assumptions!I12 -> 145553.64 | J17: ='Income-Statement'!J5/365*Assumptions!J12 -> 151386.08 | K17: ='Income-Statement'!K5/365*Assumptions!K12 -> 157448.7 | L17: ='Income-Statement'!L5/365*Assumptions!L12 -> 164533.89
B18: Accrued expenses & other current liabilities | C18: 132309 | D18: 211399 | E18: 130026 | F18: 128210 | G18: 144298 | H18: ='Income-Statement'!H4*AVERAGE('Balance-Sheet'!C18/'Income-Statement'!C4,'Balance-Sheet'!D18/'Income-Statement'!D4,'Balance-Sheet'!E18/'Income-Statement'!E4,'Balance-Sheet'!F18/'Income-Statement'!F4,'Balance-Sheet'!G18/'Income-Statement'!G4) -> 175657.48 | I18: ='Income-Statement'!I4*AVERAGE('Balance-Sheet'!C18/'Income-Statement'!C4,'Balance-Sheet'!D18/'Income-Statement'!D4,'Balance-Sheet'!E18/'Income-Statement'!E4,'Balance-Sheet'!F18/'Income-Statement'!F4,'Balance-Sheet'!G18/'Income-Statement'!G4) -> 182683.78 | J18: ='Income-Statement'!J4*AVERAGE('Balance-Sheet'!C18/'Income-Statement'!C4,'Balance-Sheet'!D18/'Income-Statement'!D4,'Balance-Sheet'!E18/'Income-Statement'!E4,'Balance-Sheet'!F18/'Income-Statement'!F4,'Balance-Sheet'!G18/'Income-Statement'!G4) -> 190904.55 | K18: ='Income-Statement'!K4*AVERAGE('Balance-Sheet'!C18/'Income-Statement'!C4,'Balance-Sheet'!D18/'Income-Statement'!D4,'Balance-Sheet'!E18/'Income-Statement'!E4,'Balance-Sheet'!F18/'Income-Statement'!F4,'Balance-Sheet'!G18/'Income-Statement'!G4) -> 199495.25 | L18: ='Income-Statement'!L4*AVERAGE('Balance-Sheet'!C18/'Income-Statement'!C4,'Balance-Sheet'!D18/'Income-Statement'!D4,'Balance-Sheet'!E18/'Income-Statement'!E4,'Balance-Sheet'!F18/'Income-Statement'!F4,'Balance-Sheet'!G18/'Income-Statement'!G4) -> 209470.02
B19: Taxes Payable | C19: 14514 | D19: 15289 | E19: 33489 | F19: 38089 | G19: 15897 | H19: =G19 -> 15897 | I19: =H19 -> 15897 | J19: =I19 -> 15897 | K19: =J19 -> 15897 | L19: =K19 -> 15897
B20: Accrued payroll & related costs | C20: 30844 | D20: 4847 | E20: 23141 | F20: 28610 | G20: 22659 | H20: ='Income-Statement'!H7*AVERAGE('Balance-Sheet'!C20/'Income-Statement'!C7,'Balance-Sheet'!D20/'Income-Statement'!D7,'Balance-Sheet'!E20/'Income-Statement'!E7,'Balance-Sheet'!F20/'Income-Statement'!F7,'Balance-Sheet'!G20/'Income-Statement'!G7) -> 28097.986 | I20: ='Income-Statement'!I7*AVERAGE('Balance-Sheet'!C20/'Income-Statement'!C7,'Balance-Sheet'!D20/'Income-Statement'!D7,'Balance-Sheet'!E20/'Income-Statement'!E7,'Balance-Sheet'!F20/'Income-Statement'!F7,'Balance-Sheet'!G20/'Income-Statement'!G7) -> 29030.077 | J20: ='Income-Statement'!J7*AVERAGE('Balance-Sheet'!C20/'Income-Statement'!C7,'Balance-Sheet'!D20/'Income-Statement'!D7,'Balance-Sheet'!E20/'Income-Statement'!E7,'Balance-Sheet'!F20/'Income-Statement'!F7,'Balance-Sheet'!G20/'Income-Statement'!G7) -> 30135.97 | K20: ='Income-Statement'!K7*AVERAGE('Balance-Sheet'!C20/'Income-Statement'!C7,'Balance-Sheet'!D20/'Income-Statement'!D7,'Balance-Sheet'!E20/'Income-Statement'!E7,'Balance-Sheet'!F20/'Income-Statement'!F7,'Balance-Sheet'!G20/'Income-Statement'!G7) -> 31352.434 | L20: ='Income-Statement'!L7*AVERAGE('Balance-Sheet'!C20/'Income-Statement'!C7,'Balance-Sheet'!D20/'Income-Statement'!D7,'Balance-Sheet'!E20/'Income-Statement'!E7,'Balance-Sheet'!F20/'Income-Statement'!F7,'Balance-Sheet'!G20/'Income-Statement'!G7) -> 32773.418
B21: Operating lease liabilities (current) | C21: 10167 | D21: 12076 | E21: 14726 | F21: 19621 | G21: 15044 | H21: =G21 -> 15044 | I21: =H21 -> 15044 | J21: =I21 -> 15044 | K21: =J21 -> 15044 | L21: =K21 -> 15044
B22: Current maturities of long-term debt | C22: 24560 | D22: 24611 | E22: 6579 | F22: 6475 | G22: 5172 | H22: =G22 -> 5172 | I22: =H22 -> 5172 | J22: =I22 -> 5172 | K22: =J22 -> 5172 | L22: =K22 -> 5172
B23: Total Current Liabilities | C23: =SUM(C17:C22) -> 403713 | D23: =SUM(D17:D22) -> 409040 | E23: =SUM(E17:E22) -> 398353 | F23: =SUM(F17:F22) -> 379504 | G23: =SUM(G17:G22) -> 334339 | H23: =SUM(H17:H22) -> 380484.05 | I23: =SUM(I17:I22) -> 393380.49 | J23: =SUM(J17:J22) -> 408539.6 | ... L23: =SUM(L17:L22) -> 442890.33
B24: Long-term debt, net | C24: 95741 | D24: 71741 | E24: 78645 | F24: 72821 | G24: 68301 | H24: =MAX(G24-4219,0) -> 64082 | I24: =MAX(H24-4219,0) -> 59863 | J24: =MAX(I24-4219,0) -> 55644 | K24: =MAX(J24-4219,0) -> 51425 | L24: =MAX(K24-4219,0) -> 47206
B25: Operating lease liabilities (non-current) | C25: 55940 | D25: 55649 | E25: 76163 | F25: 73586 | G25: 139945 | H25: =G25 -> 139945 | I25: =H25 -> 139945 | J25: =I25 -> 139945 | K25: =J25 -> 139945 | L25: =K25 -> 139945
B26: Other liabilities | C26: 23147 | D26: 13858 | E26: 20421 | F26: 20102 | G26: 42557 | H26: =G26 -> 42557 | I26: =H26 -> 42557 | J26: =I26 -> 42557 | K26: =J26 -> 42557 | L26: =K26 -> 42557
B27: Total liabilities | C27: =SUM(C23:C26) -> 578541 | D27: =SUM(D23:D26) -> 550288 | E27: =SUM(E23:E26) -> 573582 | F27: =SUM(F23:F26) -> 546013 | G27: =SUM(G23:G26) -> 585142 | H27: =SUM(H23:H26) -> 627068.05 | I27: =SUM(I23:I26) -> 635745.49 | J27: =SUM(J23:J26) -> 646685.6 | ... L27: =SUM(L23:L26) -> 672598.33
B28: STOCKHOLDERS EQUITY
B29: Common Stock | C29: 877 | D29: 881 | E29: 886 | F29: 892 | G29: 900 | H29: =G29 -> 900 | I29: =G29 -> 900 | J29: =G29 -> 900 | K29: =G29 -> 900 | L29: =G29 -> 900
B30: Treasury stock | C30: 0 | D30: -100025 | E30: -100025 | F30: -281587 | G30: -602268 | H30: =G30 -> -602268 | I30: =G30 -> -602268 | J30: =G30 -> -602268 | K30: =G30 -> -602268 | L30: =G30 -> -602268
B31: Additional paid-in capital | C31: 337735 | D31: 357490 | E31: 386377 | F31: 405921 | G31: 471770 | H31: =G31 -> 471770 | I31: =G31 -> 471770 | J31: =G31 -> 471770 | K31: =G31 -> 471770 | L31: =G31 -> 471770
B32: Retained earnings | C32: 178858 | D32: 268551 | E32: 438436 | F32: 614125 | G32: 779512 | H32: =G32+'Income-Statement'!H13 -> 949698.51 | I32: =H32+'Income-Statement'!I13 -> 1134284.4 | J32: =I32+'Income-Statement'!J13 -> 1335111.2 | K32: =J32+'Income-Statement'!K13 -> 1551611.1 | L32: =K32+'Income-Statement'!L13 -> 1785904.3
B33: Accumulated other comprehensive gain (loss) | C33: 353 | D33: -420 | E33: -2064 | F33: 756 | G33: 362 | H33: =G33 -> 362 | I33: =G33 -> 362 | J33: =G33 -> 362 | K33: =G33 -> 362 | L33: =G33 -> 362
B34: Total Stockholders Equity | C34: =SUM(C29:C33) -> 517823 | D34: =SUM(D29:D33) -> 526477 | E34: =SUM(E29:E33) -> 723610 | F34: =SUM(F29:F33) -> 740107 | G34: =SUM(G29:G33) -> 650276 | H34: =SUM(H29:H33) -> 820462.51 | I34: =SUM(I29:I33) -> 1005048.4 | J34: =SUM(J29:J33) -> 1205875.2 | ... L34: =SUM(L29:L33) -> 1656668.3
B35: Total liabilities and stockholders equity | C35: =C27+C34 -> 1096364 | D35: =D27+D34 -> 1076765 | E35: =E27+E34 -> 1297192 | F35: =F27+F34 -> 1286120 | G35: =G27+G34 -> 1235418 | H35: =H27+H34 -> 1447530.6 | I35: =I27+I34 -> 1640793.9 | J35: =J27+J34 -> 1852560.8 | ... L35: =L27+L34 -> 2329266.7
C36: =IF(C15=C35,"CHECK","BREAK") -> CHECK | D36: =IF(D15=D35,"CHECK","BREAK") -> CHECK | E36: =IF(E15=E35,"CHECK","BREAK") -> CHECK | F36: =IF(F15=F35,"CHECK","BREAK") -> CHECK | G36: =IF(G15=G35,"CHECK","BREAK") -> CHECK | H36: =IF(ROUND(H15,0)=ROUND(H35,0),"CHECK","BREAK") -> CHECK | I36: =IF(ROUND(I15,0)=ROUND(I35,0),"CHECK","BREAK") -> CHECK | J36: =IF(ROUND(J15,0)=ROUND(J35,0),"CHECK","BREAK") -> CHECK | K36: =IF(ROUND(K15,0)=ROUND(K35,0),"CHECK","BREAK") -> CHECK | L36: =IF(ROUND(L15,0)=ROUND(L35,0),"CHECK","BREAK") -> CHECK
B37: BALANCE CHECK (Assets = Liabilities + Equity) | C37: =IF(ABS(C15-C35)<1,"✓ Balanced",C15-C35) -> ✓ Balanced | D37: =IF(ABS(D15-D35)<1,"✓ Balanced",D15-D35) -> ✓ Balanced | E37: =IF(ABS(E15-E35)<1,"✓ Balanced",E15-E35) -> ✓ Balanced | F37: =IF(ABS(F15-F35)<1,"✓ Balanced",F15-F35) -> ✓ Balanced | G37: =IF(ABS(G15-G35)<1,"✓ Balanced",G15-G35) -> ✓ Balanced | H37: =IF(ABS(H15-H35)<1,"✓ Balanced",H15-H35) -> ✓ Balanced | I37: =IF(ABS(I15-I35)<1,"✓ Balanced",I15-I35) -> ✓ Balanced | J37: =IF(ABS(J15-J35)<1,"✓ Balanced",J15-J35) -> ✓ Balanced | ... L37: =IF(ABS(L15-L35)<1,"✓ Balanced",L15-L35) -> ✓ Balanced
B38: Note: Cash (row 5) is the balancing plug — it comes from CF end-of-period balance

Sheet Cash-Flow
B1: YETI Holdings, Inc. — Statement of Cash Flows (In Thousands)
C3: 2021 | D3: 2022 | E3: 2023 | F3: 2024 | G3: 2025 | H3: 2026 | I3: 2027 | J3: 2028 | K3: 2029 | L3: 2030
B4: Cash Flows from Operating Activities
B5: Net Income | C5: 212602 | D5: 89693 | E5: 169885 | F5: 175689 | G5: 165387 | H5: ='Income-Statement'!H13 -> 170186.51 | I5: ='Income-Statement'!I13 -> 184585.87 | J5: ='Income-Statement'!J13 -> 200826.84 | K5: ='Income-Statement'!K13 -> 216499.83 | L5: ='Income-Statement'!L13 -> 234293.3
B6: Depreciation & Amortization | C6: 32070 | D6: 39847 | E6: 46434 | F6: 48132 | G6: 54232 | H6: ='Income-Statement'!H4*Assumptions!H16 -> 58297.013 | I6: ='Income-Statement'!I4*Assumptions!I16 -> 60628.893 | J6: ='Income-Statement'!J4*Assumptions!J16 -> 63357.194 | K6: ='Income-Statement'!K4*Assumptions!K16 -> 66208.267 | L6: ='Income-Statement'!L4*Assumptions!L16 -> 67201.391
B7: Amortization of deferred financing fees | C7: 679 | D7: 601 | E7: 604 | F7: 649 | G7: 653 | H7: ='Cash-Flow'!G7 -> 653 | I7: ='Cash-Flow'!G7 -> 653 | J7: ='Cash-Flow'!G7 -> 653 | K7: ='Cash-Flow'!G7 -> 653 | L7: ='Cash-Flow'!G7 -> 653
B8: Stock-based Compensation | C8: 15474 | D8: 17799 | E8: 29800 | F8: 40719 | G8: 47688 | H8: ='Income-Statement'!H4*Assumptions!H17 -> 49595.52 | I8: ='Income-Statement'!I4*Assumptions!I17 -> 51579.341 | J8: ='Income-Statement'!J4*Assumptions!J17 -> 53900.411 | K8: ='Income-Statement'!K4*Assumptions!K17 -> 56325.93 | L8: ='Income-Statement'!L4*Assumptions!L17 -> 59142.226
B9: Deferred Income Taxes | C9: 5147 | D9: -403 | E9: 25561 | F9: -11167 | G9: 28081 | H9: 0 | I9: 0 | J9: 0 | K9: 0 | L9: 0
B10: Impairment of Long-Lived Assets | C10: 2473 | D10: 1229 | E10: 2927 | F10: 5490 | G10: 3795 | H10: 0 | I10: 0 | J10: 0 | K10: 0 | L10: 0
B11: Loss on Modification of Debt | C11: 0 | D11: 0 | E11: 330 | F11: 0 | G11: 0 | H11: 0 | I11: 0 | J11: 0 | K11: 0 | L11: 0
B12: Product Recalls | C12: 0 | D12: 97176 | E12: 1895 | F12: 9939 | G12: 2900 | H12: 0 | I12: 0 | J12: 0 | K12: 0 | L12: 0
B13: Other Adjustments | C13: 1022 | D13: 2039 | E13: -6163 | F13: 9872 | G13: -3881 | H13: 0 | I13: 0 | J13: 0 | K13: 0 | L13: 0
B14: Changes in Operating Assets and Liabilities
B15: Accounts Receivable | C15: -44681 | D15: 30448 | E15: -15683 | F15: -23655 | G15: -18161 | H15: =-('Balance-Sheet'!H6-'Balance-Sheet'!G6) -> -7645.9871 | I15: =-('Balance-Sheet'!I6-'Balance-Sheet'!H6) -> -5962.7995 | J15: =-('Balance-Sheet'!J6-'Balance-Sheet'!I6) -> -6976.4754 | K15: =-('Balance-Sheet'!K6-'Balance-Sheet'!J6) -> -7290.4168 | L15: =-('Balance-Sheet'!L6-'Balance-Sheet'!K6) -> -8464.9839
B16: Inventory | C16: -179803 | D16: -91624 | E16: 33675 | F16: 39751 | G16: 23857 | H16: =-('Balance-Sheet'!H7-'Balance-Sheet'!G7) -> -15568.106 | I16: =-('Balance-Sheet'!I7-'Balance-Sheet'!H7) -> -6056.9265 | J16: =-('Balance-Sheet'!J7-'Balance-Sheet'!I7) -> -7628.1114 | K16: =-('Balance-Sheet'!K7-'Balance-Sheet'!J7) -> -10270.23 | L16: =-('Balance-Sheet'!L7-'Balance-Sheet'!K7) -> -14856.047
B17: Other Current Assets | C17: -10587 | D17: -2187 | E17: -7933 | F17: 9480 | G17: 6614 | H17: 0 | I17: 0 | J17: 0 | K17: 0 | L17: 0
B18: Accounts Payable & Accrued Expenses | C18: 112773 | D18: -86242 | E18: -15144 | F18: -47020 | G18: -27687 | H18: =('Balance-Sheet'!H17-'Balance-Sheet'!G17)+('Balance-Sheet'!H18-'Balance-Sheet'!G18) -> 40706.068 | I18: =('Balance-Sheet'!I17-'Balance-Sheet'!H17)+('Balance-Sheet'!I18-'Balance-Sheet'!H18) -> 11964.349 | J18: =('Balance-Sheet'!J17-'Balance-Sheet'!I17)+('Balance-Sheet'!J18-'Balance-Sheet'!I18) -> 14053.214 | K18: =('Balance-Sheet'!K17-'Balance-Sheet'!J17)+('Balance-Sheet'!K18-'Balance-Sheet'!J18) -> 14653.323 | L18: =('Balance-Sheet'!L17-'Balance-Sheet'!K17)+('Balance-Sheet'!L18-'Balance-Sheet'!K18) -> 17059.954
B19: Taxes Payable CF | C19: -3781 | D19: 439 | E19: 18156 | F19: 669 | G19: -23941 | H19: ='Balance-Sheet'!H19-'Balance-Sheet'!G19 -> 0 | I19: ='Balance-Sheet'!I19-'Balance-Sheet'!H19 -> 0 | J19: ='Balance-Sheet'!J19-'Balance-Sheet'!I19 -> 0 | K19: ='Balance-Sheet'!K19-'Balance-Sheet'!J19 -> 0 | L19: ='Balance-Sheet'!L19-'Balance-Sheet'!K19 -> 0
B20: Other Operating | C20: 3132 | D20: 2079 | E20: 1598 | F20: 2838 | G20: -4800 | H20: 0 | I20: 0 | J20: 0 | K20: 0 | L20: 0
B21: Net Cash from Operating Activities | C21: =SUM(C5:C20) -> 146520 | D21: =SUM(D5:D20) -> 100894 | E21: =SUM(E5:E20) -> 285942 | F21: =SUM(F5:F20) -> 261386 | G21: =SUM(G5:G20) -> 254737 | H21: =SUM(H5:H20) -> 296224.02 | I21: =SUM(I5:I20) -> 297391.73 | J21: =SUM(J5:J20) -> 318186.07 | ... L21: =SUM(L5:L20) -> 355028.84
B22: Cash Flows from Investing Activities
B23: Purchases of property and equipment | C23: -56121 | D23: -45929 | E23: -50672 | F23: -41832 | G23: -42667 | H23: =-'Income-Statement'!H4*Assumptions!H15 -> -46637.61 | I23: =-'Income-Statement'!I4*Assumptions!I15 -> -48503.115 | J23: =-'Income-Statement'!J4*Assumptions!J15 -> -48573.848 | K23: =-'Income-Statement'!K4*Assumptions!K15 -> -50759.672 | L23: =-'Income-Statement'!L4*Assumptions!L15 -> -53297.655
B24: Business Acquisition, net | C24: 0 | D24: 0 | E24: 0 | F24: -36164 | G24: 0 | H24: 0 | I24: 0 | J24: 0 | K24: 0 | L24: 0
B25: Additions of Intangibles, net | C25: -9635 | D25: -10981 | E25: -22152 | F25: -53452 | G25: -59172 | H25: =AVERAGE('Cash-Flow'!C25:G25) -> -31078.4 | I25: =AVERAGE('Cash-Flow'!C25:G25) -> -31078.4 | J25: =AVERAGE('Cash-Flow'!C25:G25) -> -31078.4 | K25: =AVERAGE('Cash-Flow'!C25:G25) -> -31078.4 | L25: =AVERAGE('Cash-Flow'!C25:G25) -> -31078.4
B26: Net Cash from Investing Activities | C26: =SUM(C23:C25) -> -65756 | D26: =SUM(D23:D25) -> -56910 | E26: =SUM(E23:E25) -> -72824 | F26: =SUM(F23:F25) -> -131448 | G26: =SUM(G23:G25) -> -101839 | H26: =SUM(H23:H25) -> -77716.01 | I26: =SUM(I23:I25) -> -79581.515 | J26: =SUM(J23:J25) -> -79652.248 | ... L26: =SUM(L23:L25) -> -84376.055
B27: Cash Flows from Financing Activities
B28: Repayments of Long-Term Debt | C28: -22500 | D28: -22500 | E28: -7734 | F28: -4219 | G28: -4219 | H28: ='Cash-Flow'!G28 -> -4219 | I28: ='Cash-Flow'!G28 -> -4219 | J28: ='Cash-Flow'!G28 -> -4219 | K28: ='Cash-Flow'!G28 -> -4219 | L28: ='Cash-Flow'!G28 -> -4219
B29: Taxes paid on Employee Stock Transactions | C29: -3506 | D29: -1861 | E29: -2481 | F29: -1463 | G29: -1831 | H29: ='Cash-Flow'!G29 -> -1831 | I29: ='Cash-Flow'!G29 -> -1831 | J29: ='Cash-Flow'!G29 -> -1831 | K29: ='Cash-Flow'!G29 -> -1831 | L29: ='Cash-Flow'!G29 -> -1831
B30: Proceeds from Employee Stock Transactions | C30: 4095 | D30: 3821 | E30: -2824 | F30: 294 | G30: 0 | H30: 0 | I30: 0 | J30: 0 | K30: 0 | L30: 0
B31: Finance Lease Repayments | C31: -1108 | D31: -2063 | E31: 1573 | F31: -3829 | G31: -16000 | H31: ='Cash-Flow'!G31 -> -16000 | I31: ='Cash-Flow'!G31 -> -16000 | J31: ='Cash-Flow'!G31 -> -16000 | K31: ='Cash-Flow'!G31 -> -16000 | L31: ='Cash-Flow'!G31 -> -16000
B32: Repurchase of Common Stock | C32: 0 | D32: -100025 | E32: -2130 | F32: -200000 | G32: -297780 | H32: 0 | I32: 0 | J32: 0 | K32: 0 | L32: 0
B33: Excise Tax on Stock Repurchase | C33: 0 | D33: 0 | E33: 0 | F33: 0 | G33: -1562 | H33: 0 | I33: 0 | J33: 0 | K33: 0 | L33: 0
B34: Net Cash from Financing Activities | C34: =SUM(C28:C33) -> -23019 | D34: =SUM(D28:D33) -> -122628 | E34: =SUM(E28:E33) -> -13596 | F34: =SUM(F28:F33) -> -209217 | G34: =SUM(G28:G33) -> -321392 | H34: =SUM(H28:H33) -> -22050 | I34: =SUM(I28:I33) -> -22050 | J34: =SUM(J28:J33) -> -22050 | ... L34: =SUM(L28:L33) -> -22050
B35: Effect of Exchange Rate Changes | C35: 1161 | D35: 1196 | E35: 4697 | F35: -886 | G35: -1959 | H35: 0 | I35: 0 | J35: 0 | K35: 0 | L35: 0
B36: Net Change in Cash | C36: =SUM(C21,C26,C34,C35) -> 58906 | D36: =SUM(D21,D26,D34,D35) -> -77448 | E36: =SUM(E21,E26,E34,E35) -> 204219 | F36: =SUM(F21,F26,F34,F35) -> -80165 | G36: =SUM(G21,G26,G34,G35) -> -170453 | H36: ='Balance-Sheet'!H5-'Balance-Sheet'!G5 -> 197969.4 | I36: ='Balance-Sheet'!I5-'Balance-Sheet'!H5 -> 191667.87 | J36: ='Balance-Sheet'!J5-'Balance-Sheet'!I5 -> 209954.95 | K36: ='Balance-Sheet'!K5-'Balance-Sheet'!J5 -> 223958.22 | L36: ='Balance-Sheet'!L5-'Balance-Sheet'!K5 -> 236722.44
B37: Cash, beginning of period | C37: 253283 | D37: 312189 | E37: 234741 | F37: 438960 | G37: 358795 | H37: =G38 -> 188342 | I37: =H38 -> 386311.4 | J37: =I38 -> 577979.27 | K37: =J38 -> 787934.22 | L37: =K38 -> 1011892.4
B38: Cash, end of period | C38: =IFERROR(C37+C36,0) -> 312189 | D38: =IFERROR(D37+D36,0) -> 234741 | E38: =IFERROR(E37+E36,0) -> 438960 | F38: =IFERROR(F37+F36,0) -> 358795 | G38: =IFERROR(G37+G36,0) -> 188342 | H38: ='Balance-Sheet'!H5 -> 386311.4 | I38: ='Balance-Sheet'!I5 -> 577979.27 | J38: ='Balance-Sheet'!J5 -> 787934.22 | K38: ='Balance-Sheet'!K5 -> 1011892.4 | L38: ='Balance-Sheet'!L5 -> 1248614.9

Sheet Forecasts & DCF
B1: YETI Holdings, Inc. — Discounted Cash Flow Valuation
B2: ($ in thousands, EXCEPT per share data)
B3: → Projected financials flow from Income Statement, Balance Sheet, and Cash Flow tabs.
B4: DCF ASSUMPTIONS
B5: WACC | C5: 0.09 | D5: ← change to run scenarios
B6: Terminal Growth Rate | C6: 0.025
B7: Tax Rate | C7: 0.25
B8: Shares Outstanding (thou) | C8: 83500 | D8: ← from latest 10-K (not in 3-statement; update as needed)
B9: Net Debt / (Cash) | C9: ='Balance-Sheet'!G24+'Balance-Sheet'!G22-'Balance-Sheet'!G5 -> -114869 | D9: = LT Debt + Current Debt − Cash (BS rows 24+22−5, col G)
B10: EV/EBITDA Exit Multiple | C10: 12 | D10: ← trailing actual: =C40/(Forecasts & DCF not self-ref; see below)
B11: Trailing EV/EBITDA (ref, 2025) | C11: =IFERROR(C40/('Income-Statement'!G8+'Cash-Flow'!G6),0) -> 12.391267 | D11: ← implied EV/EBITDA at DCF's own EV (sanity check)
B13: EBITDA Calculation (bridge from IS)
C14: ='Income-Statement'!H3 -> 2026 | D14: ='Income-Statement'!I3 -> 2027 | E14: ='Income-Statement'!J3 -> 2028 | F14: ='Income-Statement'!K3 -> 2029 | G14: ='Income-Statement'!L3 -> 2030
B15: Operating Income (EBIT) | C15: ='Income-Statement'!H8 -> 227358.35 | D15: ='Income-Statement'!I8 -> 246557.5 | E15: ='Income-Statement'!J8 -> 268212.12 | F15: ='Income-Statement'!K8 -> 289109.43 | G15: ='Income-Statement'!L8 -> 312834.06
B16: + Depreciation & Amortization | C16: ='Cash-Flow'!H6 -> 58297.013 | D16: ='Cash-Flow'!I6 -> 60628.893 | E16: ='Cash-Flow'!J6 -> 63357.194 | F16: ='Cash-Flow'!K6 -> 66208.267 | G16: ='Cash-Flow'!L6 -> 67201.391
B17: EBITDA | C17: =C15+C16 -> 285655.36 | D17: =D15+D16 -> 307186.39 | E17: =E15+E16 -> 331569.31 | F17: =F15+F16 -> 355317.7 | G17: =G15+G16 -> 380035.45
B18: EBITDA Margin % | C18: =C17/'Income-Statement'!H4 -> 0.147 | D18: =D17/'Income-Statement'!I4 -> 0.152 | E18: =E17/'Income-Statement'!J4 -> 0.157 | F18: =F17/'Income-Statement'!K4 -> 0.161 | G18: =G17/'Income-Statement'!L4 -> 0.164
B20: FREE CASH FLOW BUILD
B21: EBIT (Operating Income) | C21: =C15 -> 227358.35 | D21: =D15 -> 246557.5 | E21: =E15 -> 268212.12 | F21: =F15 -> 289109.43 | G21: =G15 -> 312834.06
B22: NOPAT = EBIT × (1 − Tax Rate) | C22: =C21*(1-$C$7) -> 170518.76 | D22: =D21*(1-$C$7) -> 184918.12 | E22: =E21*(1-$C$7) -> 201159.09 | F22: =F21*(1-$C$7) -> 216832.08 | G22: =G21*(1-$C$7) -> 234625.55
B23: + D&A | C23: =C16 -> 58297.013 | D23: =D16 -> 60628.893 | E23: =E16 -> 63357.194 | F23: =F16 -> 66208.267 | G23: =G16 -> 67201.391
B24: − Capex | C24: ='Cash-Flow'!H23 -> -46637.61 | D24: ='Cash-Flow'!I23 -> -48503.115 | E24: ='Cash-Flow'!J23 -> -48573.848 | F24: ='Cash-Flow'!K23 -> -50759.672 | G24: ='Cash-Flow'!L23 -> -53297.655
B25: − Change in Net Working Capital | C25: =SUM('Cash-Flow'!H15:H20) -> 17491.975 | D25: =SUM('Cash-Flow'!I15:I20) -> -55.377064 | E25: =SUM('Cash-Flow'!J15:J20) -> -551.37264 | F25: =SUM('Cash-Flow'!K15:K20) -> -2907.3241 | G25: =SUM('Cash-Flow'!L15:L20) -> -6261.0766
B26: Unlevered Free Cash Flow (UFCF) | C26: =SUM(C22:C25) -> 199670.14 | D26: =SUM(D22:D25) -> 196988.53 | E26: =SUM(E22:E25) -> 215391.06 | F26: =SUM(F22:F25) -> 229373.35 | G26: =SUM(G22:G25) -> 242268.21
B27: FCF Margin % | C27: =C26/'Income-Statement'!H4 -> 0.10275148 | D27: =D26/'Income-Statement'!I4 -> 0.097472599 | E27: =E26/'Income-Statement'!J4 -> 0.10198892 | F27: =F26/'Income-Statement'!K4 -> 0.10393265 | G27: =G26/'Income-Statement'!L4 -> 0.1045481
B29: DCF CALCULATION
B30: Period | C30: 1 | D30: 2 | E30: 3 | F30: 4 | G30: 5
B31: Unlevered FCF | C31: =C26 -> 199670.14 | D31: =D26 -> 196988.53 | E31: =E26 -> 215391.06 | F31: =F26 -> 229373.35 | G31: =G26 -> 242268.21
B32: Discount Factor | C32: =IFERROR(1/(1+$C$5)^C30,0) -> 0.91743119 | D32: =IFERROR(1/(1+$C$5)^D30,0) -> 0.84167999 | E32: =IFERROR(1/(1+$C$5)^E30,0) -> 0.77218348 | F32: =IFERROR(1/(1+$C$5)^F30,0) -> 0.70842521 | G32: =IFERROR(1/(1+$C$5)^G30,0) -> 0.64993139
B33: PV of FCF | C33: =C31*C32 -> 183183.61 | D33: =D31*D32 -> 165801.3 | E33: =E31*E32 -> 166321.42 | F33: =F31*F32 -> 162493.86 | G33: =G31*G32 -> 157457.71
B35: Sum of PV of FCFs | C35: =NPV($C$5,C26:G26) -> 835257.91 | D35: ← NPV(WACC, FCF_2026:FCF_2030)
B36: Terminal Value (Gordon Growth) | C36: =IFERROR(G26*(1+$C$6)/($C$5-$C$6),0) -> 3820383.3 | D36: ← Gordon Growth: FCF_final × (1+g) ÷ (WACC − g)
B37: PV of Terminal Value | C37: =IFERROR(C36/(1+$C$5)^5,0) -> 2482987
B38: TV as % of Enterprise Value | C38: =IFERROR(C37/(C35+C37),0) -> 0.74828322
B40: Enterprise Value | C40: =SUM(C35,C37) -> 3318244.9 | D40: ← PV of FCFs + PV of Terminal Value
B41: Less: Net Debt | C41: =-$C$9 -> 114869
B42: Equity Value | C42: =SUM(C40,C41) -> 3433113.9
B43: Implied Share Price | C43: =IFERROR(C42/$C$8,0) -> 41.115136 | D43: ← Equity Value ÷ Shares Outstanding
B44: Current Share Price (as of model date) | C44: 33.5
B45: Implied Upside / (Downside) | C45: =IFERROR((C43-C44)/C44,0) -> 0.22731751
...
